{
 "cells": [
  {
   "cell_type": "code",
   "execution_count": null,
   "metadata": {},
   "outputs": [],
   "source": [
    "%pip install msal requests\n",
    "%pip install msgraph-sdk"
   ]
  },
  {
   "cell_type": "code",
   "execution_count": 15,
   "metadata": {},
   "outputs": [],
   "source": [
    "from msal import ConfidentialClientApplication\n",
    "import requests\n",
    "from msgraph import GraphServiceClient\n",
    "import nest_asyncio\n",
    "\n",
    "nest_asyncio.apply()\n",
    "\n",
    "# Azure AD app credentials\n",
    "# client_id = \"27155167-000b-4fce-9a17-72dd18df215a\"\n",
    "# client_secret = \"S2G8Q~bieu-lD6QJV.yf0gU1bz-wth22I4uHwb26\"\n",
    "client_id = \"177d41bc-a4ec-48d3-b5c5-0a6dbb530145\"\n",
    "client_secret = \"1FX8Q~j7F3g~WYBDOpHGLhK~xnFyxYq2M8ppZcfx\"\n",
    "tenant_id = \"32d3cb4d-804d-4a6f-ab83-60ceb9dd5ffa\"\n",
    "principal_name = \"supakornemch@ponlove97hotmail.onmicrosoft.com\"\n",
    "principal_id = \"44dc3275-9194-4d68-b3f8-fc42343e9d52\""
   ]
  },
  {
   "cell_type": "code",
   "execution_count": 16,
   "metadata": {},
   "outputs": [],
   "source": [
    "from azure.identity import ClientSecretCredential\n",
    "from msgraph.graph_service_client import GraphServiceClient\n",
    "\n",
    "# Initialize the credential\n",
    "credential = ClientSecretCredential(tenant_id=tenant_id, client_id=client_id, client_secret=client_secret)\n",
    "\n",
    "# Get a token for the Microsoft Graph API\n",
    "token = credential.get_token(\"https://graph.microsoft.com/.default\")\n",
    "\n",
    "\n",
    "# Initialize the Graph client\n",
    "graph_client = GraphServiceClient(credential, [\"https://graph.microsoft.com/.default\"])"
   ]
  },
  {
   "cell_type": "code",
   "execution_count": 17,
   "metadata": {},
   "outputs": [
    {
     "ename": "ODataError",
     "evalue": "\n        APIError\n        Code: 403\n        message: None\n        error: MainError(additional_data={}, code='Authorization_RequestDenied', details=None, inner_error=InnerError(additional_data={'date': DateTime(2023, 12, 17, 9, 57, 14, tzinfo=Timezone('UTC'))}, client_request_id='765f82c5-363f-41ac-976c-b1e356146100', date=None, odata_type=None, request_id='77ce75ce-c06e-4397-8f3f-fe4fddffd6ac'), message='Insufficient privileges to complete the operation.', target=None)\n        ",
     "output_type": "error",
     "traceback": [
      "\u001b[0;31m---------------------------------------------------------------------------\u001b[0m",
      "\u001b[0;31mODataError\u001b[0m                                Traceback (most recent call last)",
      "\u001b[1;32m/Users/supakornemchananon/workspace/Personal/dimsummaster/dev.ipynb Cell 4\u001b[0m line \u001b[0;36m1\n\u001b[1;32m      <a href='vscode-notebook-cell:/Users/supakornemchananon/workspace/Personal/dimsummaster/dev.ipynb#X14sZmlsZQ%3D%3D?line=5'>6</a>\u001b[0m         \u001b[39mfor\u001b[39;00m user \u001b[39min\u001b[39;00m users\u001b[39m.\u001b[39mvalue:\n\u001b[1;32m      <a href='vscode-notebook-cell:/Users/supakornemchananon/workspace/Personal/dimsummaster/dev.ipynb#X14sZmlsZQ%3D%3D?line=6'>7</a>\u001b[0m             \u001b[39mprint\u001b[39m(user\u001b[39m.\u001b[39mid, user\u001b[39m.\u001b[39mdisplay_name, user\u001b[39m.\u001b[39mmail)\n\u001b[0;32m---> <a href='vscode-notebook-cell:/Users/supakornemchananon/workspace/Personal/dimsummaster/dev.ipynb#X14sZmlsZQ%3D%3D?line=9'>10</a>\u001b[0m asyncio\u001b[39m.\u001b[39;49mrun(get_users())\n",
      "File \u001b[0;32m~/Library/Python/3.11/lib/python/site-packages/nest_asyncio.py:31\u001b[0m, in \u001b[0;36m_patch_asyncio.<locals>.run\u001b[0;34m(main, debug)\u001b[0m\n\u001b[1;32m     29\u001b[0m task \u001b[39m=\u001b[39m asyncio\u001b[39m.\u001b[39mensure_future(main)\n\u001b[1;32m     30\u001b[0m \u001b[39mtry\u001b[39;00m:\n\u001b[0;32m---> 31\u001b[0m     \u001b[39mreturn\u001b[39;00m loop\u001b[39m.\u001b[39;49mrun_until_complete(task)\n\u001b[1;32m     32\u001b[0m \u001b[39mfinally\u001b[39;00m:\n\u001b[1;32m     33\u001b[0m     \u001b[39mif\u001b[39;00m \u001b[39mnot\u001b[39;00m task\u001b[39m.\u001b[39mdone():\n",
      "File \u001b[0;32m~/Library/Python/3.11/lib/python/site-packages/nest_asyncio.py:99\u001b[0m, in \u001b[0;36m_patch_loop.<locals>.run_until_complete\u001b[0;34m(self, future)\u001b[0m\n\u001b[1;32m     96\u001b[0m \u001b[39mif\u001b[39;00m \u001b[39mnot\u001b[39;00m f\u001b[39m.\u001b[39mdone():\n\u001b[1;32m     97\u001b[0m     \u001b[39mraise\u001b[39;00m \u001b[39mRuntimeError\u001b[39;00m(\n\u001b[1;32m     98\u001b[0m         \u001b[39m'\u001b[39m\u001b[39mEvent loop stopped before Future completed.\u001b[39m\u001b[39m'\u001b[39m)\n\u001b[0;32m---> 99\u001b[0m \u001b[39mreturn\u001b[39;00m f\u001b[39m.\u001b[39;49mresult()\n",
      "File \u001b[0;32m/opt/homebrew/Cellar/python@3.11/3.11.6/Frameworks/Python.framework/Versions/3.11/lib/python3.11/asyncio/futures.py:203\u001b[0m, in \u001b[0;36mFuture.result\u001b[0;34m(self)\u001b[0m\n\u001b[1;32m    201\u001b[0m \u001b[39mself\u001b[39m\u001b[39m.\u001b[39m__log_traceback \u001b[39m=\u001b[39m \u001b[39mFalse\u001b[39;00m\n\u001b[1;32m    202\u001b[0m \u001b[39mif\u001b[39;00m \u001b[39mself\u001b[39m\u001b[39m.\u001b[39m_exception \u001b[39mis\u001b[39;00m \u001b[39mnot\u001b[39;00m \u001b[39mNone\u001b[39;00m:\n\u001b[0;32m--> 203\u001b[0m     \u001b[39mraise\u001b[39;00m \u001b[39mself\u001b[39m\u001b[39m.\u001b[39m_exception\u001b[39m.\u001b[39mwith_traceback(\u001b[39mself\u001b[39m\u001b[39m.\u001b[39m_exception_tb)\n\u001b[1;32m    204\u001b[0m \u001b[39mreturn\u001b[39;00m \u001b[39mself\u001b[39m\u001b[39m.\u001b[39m_result\n",
      "File \u001b[0;32m/opt/homebrew/Cellar/python@3.11/3.11.6/Frameworks/Python.framework/Versions/3.11/lib/python3.11/asyncio/tasks.py:277\u001b[0m, in \u001b[0;36mTask.__step\u001b[0;34m(***failed resolving arguments***)\u001b[0m\n\u001b[1;32m    273\u001b[0m \u001b[39mtry\u001b[39;00m:\n\u001b[1;32m    274\u001b[0m     \u001b[39mif\u001b[39;00m exc \u001b[39mis\u001b[39;00m \u001b[39mNone\u001b[39;00m:\n\u001b[1;32m    275\u001b[0m         \u001b[39m# We use the `send` method directly, because coroutines\u001b[39;00m\n\u001b[1;32m    276\u001b[0m         \u001b[39m# don't have `__iter__` and `__next__` methods.\u001b[39;00m\n\u001b[0;32m--> 277\u001b[0m         result \u001b[39m=\u001b[39m coro\u001b[39m.\u001b[39msend(\u001b[39mNone\u001b[39;00m)\n\u001b[1;32m    278\u001b[0m     \u001b[39melse\u001b[39;00m:\n\u001b[1;32m    279\u001b[0m         result \u001b[39m=\u001b[39m coro\u001b[39m.\u001b[39mthrow(exc)\n",
      "\u001b[1;32m/Users/supakornemchananon/workspace/Personal/dimsummaster/dev.ipynb Cell 4\u001b[0m line \u001b[0;36m4\n\u001b[1;32m      <a href='vscode-notebook-cell:/Users/supakornemchananon/workspace/Personal/dimsummaster/dev.ipynb#X14sZmlsZQ%3D%3D?line=2'>3</a>\u001b[0m \u001b[39masync\u001b[39;00m \u001b[39mdef\u001b[39;00m \u001b[39mget_users\u001b[39m():\n\u001b[0;32m----> <a href='vscode-notebook-cell:/Users/supakornemchananon/workspace/Personal/dimsummaster/dev.ipynb#X14sZmlsZQ%3D%3D?line=3'>4</a>\u001b[0m     users \u001b[39m=\u001b[39m \u001b[39mawait\u001b[39;00m graph_client\u001b[39m.\u001b[39musers\u001b[39m.\u001b[39mget()\n\u001b[1;32m      <a href='vscode-notebook-cell:/Users/supakornemchananon/workspace/Personal/dimsummaster/dev.ipynb#X14sZmlsZQ%3D%3D?line=4'>5</a>\u001b[0m     \u001b[39mif\u001b[39;00m users \u001b[39mand\u001b[39;00m users\u001b[39m.\u001b[39mvalue:\n\u001b[1;32m      <a href='vscode-notebook-cell:/Users/supakornemchananon/workspace/Personal/dimsummaster/dev.ipynb#X14sZmlsZQ%3D%3D?line=5'>6</a>\u001b[0m         \u001b[39mfor\u001b[39;00m user \u001b[39min\u001b[39;00m users\u001b[39m.\u001b[39mvalue:\n",
      "File \u001b[0;32m/opt/homebrew/lib/python3.11/site-packages/msgraph/generated/users/users_request_builder.py:70\u001b[0m, in \u001b[0;36mUsersRequestBuilder.get\u001b[0;34m(self, request_configuration)\u001b[0m\n\u001b[1;32m     67\u001b[0m     \u001b[39mraise\u001b[39;00m \u001b[39mException\u001b[39;00m(\u001b[39m\"\u001b[39m\u001b[39mHttp core is null\u001b[39m\u001b[39m\"\u001b[39m) \n\u001b[1;32m     68\u001b[0m \u001b[39mfrom\u001b[39;00m \u001b[39m.\u001b[39;00m\u001b[39m.\u001b[39;00m\u001b[39mmodels\u001b[39;00m\u001b[39m.\u001b[39;00m\u001b[39muser_collection_response\u001b[39;00m \u001b[39mimport\u001b[39;00m UserCollectionResponse\n\u001b[0;32m---> 70\u001b[0m \u001b[39mreturn\u001b[39;00m \u001b[39mawait\u001b[39;00m \u001b[39mself\u001b[39m\u001b[39m.\u001b[39mrequest_adapter\u001b[39m.\u001b[39msend_async(request_info, UserCollectionResponse, error_mapping)\n",
      "File \u001b[0;32m/opt/homebrew/lib/python3.11/site-packages/kiota_http/httpx_request_adapter.py:185\u001b[0m, in \u001b[0;36mHttpxRequestAdapter.send_async\u001b[0;34m(self, request_info, parsable_factory, error_map)\u001b[0m\n\u001b[1;32m    182\u001b[0m     parent_span\u001b[39m.\u001b[39madd_event(RESPONSE_HANDLER_EVENT_INVOKED_KEY)\n\u001b[1;32m    183\u001b[0m     \u001b[39mreturn\u001b[39;00m \u001b[39mawait\u001b[39;00m response_handler\u001b[39m.\u001b[39mhandle_response_async(response, error_map)\n\u001b[0;32m--> 185\u001b[0m \u001b[39mawait\u001b[39;00m \u001b[39mself\u001b[39m\u001b[39m.\u001b[39mthrow_failed_responses(response, error_map, parent_span, parent_span)\n\u001b[1;32m    186\u001b[0m \u001b[39mif\u001b[39;00m \u001b[39mself\u001b[39m\u001b[39m.\u001b[39m_should_return_none(response):\n\u001b[1;32m    187\u001b[0m     \u001b[39mreturn\u001b[39;00m \u001b[39mNone\u001b[39;00m\n",
      "File \u001b[0;32m/opt/homebrew/lib/python3.11/site-packages/kiota_http/httpx_request_adapter.py:501\u001b[0m, in \u001b[0;36mHttpxRequestAdapter.throw_failed_responses\u001b[0;34m(self, response, error_map, parent_span, attribute_span)\u001b[0m\n\u001b[1;32m    492\u001b[0m         exc \u001b[39m=\u001b[39m APIError(\n\u001b[1;32m    493\u001b[0m             (\n\u001b[1;32m    494\u001b[0m                 \u001b[39m\"\u001b[39m\u001b[39mThe server returned an unexpected status code and the error registered\u001b[39m\u001b[39m\"\u001b[39m\n\u001b[0;32m   (...)\u001b[0m\n\u001b[1;32m    498\u001b[0m             response_headers,\n\u001b[1;32m    499\u001b[0m         )\n\u001b[1;32m    500\u001b[0m     _get_obj_span\u001b[39m.\u001b[39mend()\n\u001b[0;32m--> 501\u001b[0m     \u001b[39mraise\u001b[39;00m exc\n\u001b[1;32m    502\u001b[0m \u001b[39mfinally\u001b[39;00m:\n\u001b[1;32m    503\u001b[0m     _throw_failed_resp_span\u001b[39m.\u001b[39mend()\n",
      "\u001b[0;31mODataError\u001b[0m: \n        APIError\n        Code: 403\n        message: None\n        error: MainError(additional_data={}, code='Authorization_RequestDenied', details=None, inner_error=InnerError(additional_data={'date': DateTime(2023, 12, 17, 9, 57, 14, tzinfo=Timezone('UTC'))}, client_request_id='765f82c5-363f-41ac-976c-b1e356146100', date=None, odata_type=None, request_id='77ce75ce-c06e-4397-8f3f-fe4fddffd6ac'), message='Insufficient privileges to complete the operation.', target=None)\n        "
     ]
    }
   ],
   "source": [
    "import asyncio\n",
    "\n",
    "async def get_users():\n",
    "    users = await graph_client.users.get()\n",
    "    if users and users.value:\n",
    "        for user in users.value:\n",
    "            print(user.id, user.display_name, user.mail)\n",
    "\n",
    "\n",
    "asyncio.run(get_users())"
   ]
  },
  {
   "cell_type": "code",
   "execution_count": 18,
   "metadata": {},
   "outputs": [
    {
     "ename": "ODataError",
     "evalue": "\n        APIError\n        Code: 400\n        message: None\n        error: MainError(additional_data={}, code='BadRequest', details=None, inner_error=InnerError(additional_data={'date': DateTime(2023, 12, 17, 9, 58, 2, tzinfo=Timezone('UTC'))}, client_request_id='4e56b300-04c3-4030-bbf4-3b09e5c67395', date=None, odata_type=None, request_id='9f671f36-972e-4fbf-ab9e-a4ffc9fedfc0'), message='Tenant does not have a SPO license.', target=None)\n        ",
     "output_type": "error",
     "traceback": [
      "\u001b[0;31m---------------------------------------------------------------------------\u001b[0m",
      "\u001b[0;31mODataError\u001b[0m                                Traceback (most recent call last)",
      "\u001b[1;32m/Users/supakornemchananon/workspace/Personal/dimsummaster/dev.ipynb Cell 5\u001b[0m line \u001b[0;36m8\n\u001b[1;32m      <a href='vscode-notebook-cell:/Users/supakornemchananon/workspace/Personal/dimsummaster/dev.ipynb#X15sZmlsZQ%3D%3D?line=3'>4</a>\u001b[0m         \u001b[39mfor\u001b[39;00m drive \u001b[39min\u001b[39;00m drives\u001b[39m.\u001b[39mvalue:\n\u001b[1;32m      <a href='vscode-notebook-cell:/Users/supakornemchananon/workspace/Personal/dimsummaster/dev.ipynb#X15sZmlsZQ%3D%3D?line=4'>5</a>\u001b[0m             \u001b[39mprint\u001b[39m(drive\u001b[39m.\u001b[39mid, drive\u001b[39m.\u001b[39mdrive_type, drive\u001b[39m.\u001b[39mname, drive\u001b[39m.\u001b[39mdescription, drive\u001b[39m.\u001b[39mweb_url)\n\u001b[0;32m----> <a href='vscode-notebook-cell:/Users/supakornemchananon/workspace/Personal/dimsummaster/dev.ipynb#X15sZmlsZQ%3D%3D?line=7'>8</a>\u001b[0m asyncio\u001b[39m.\u001b[39;49mrun(get_drives())\n",
      "File \u001b[0;32m~/Library/Python/3.11/lib/python/site-packages/nest_asyncio.py:31\u001b[0m, in \u001b[0;36m_patch_asyncio.<locals>.run\u001b[0;34m(main, debug)\u001b[0m\n\u001b[1;32m     29\u001b[0m task \u001b[39m=\u001b[39m asyncio\u001b[39m.\u001b[39mensure_future(main)\n\u001b[1;32m     30\u001b[0m \u001b[39mtry\u001b[39;00m:\n\u001b[0;32m---> 31\u001b[0m     \u001b[39mreturn\u001b[39;00m loop\u001b[39m.\u001b[39;49mrun_until_complete(task)\n\u001b[1;32m     32\u001b[0m \u001b[39mfinally\u001b[39;00m:\n\u001b[1;32m     33\u001b[0m     \u001b[39mif\u001b[39;00m \u001b[39mnot\u001b[39;00m task\u001b[39m.\u001b[39mdone():\n",
      "File \u001b[0;32m~/Library/Python/3.11/lib/python/site-packages/nest_asyncio.py:99\u001b[0m, in \u001b[0;36m_patch_loop.<locals>.run_until_complete\u001b[0;34m(self, future)\u001b[0m\n\u001b[1;32m     96\u001b[0m \u001b[39mif\u001b[39;00m \u001b[39mnot\u001b[39;00m f\u001b[39m.\u001b[39mdone():\n\u001b[1;32m     97\u001b[0m     \u001b[39mraise\u001b[39;00m \u001b[39mRuntimeError\u001b[39;00m(\n\u001b[1;32m     98\u001b[0m         \u001b[39m'\u001b[39m\u001b[39mEvent loop stopped before Future completed.\u001b[39m\u001b[39m'\u001b[39m)\n\u001b[0;32m---> 99\u001b[0m \u001b[39mreturn\u001b[39;00m f\u001b[39m.\u001b[39;49mresult()\n",
      "File \u001b[0;32m/opt/homebrew/Cellar/python@3.11/3.11.6/Frameworks/Python.framework/Versions/3.11/lib/python3.11/asyncio/futures.py:203\u001b[0m, in \u001b[0;36mFuture.result\u001b[0;34m(self)\u001b[0m\n\u001b[1;32m    201\u001b[0m \u001b[39mself\u001b[39m\u001b[39m.\u001b[39m__log_traceback \u001b[39m=\u001b[39m \u001b[39mFalse\u001b[39;00m\n\u001b[1;32m    202\u001b[0m \u001b[39mif\u001b[39;00m \u001b[39mself\u001b[39m\u001b[39m.\u001b[39m_exception \u001b[39mis\u001b[39;00m \u001b[39mnot\u001b[39;00m \u001b[39mNone\u001b[39;00m:\n\u001b[0;32m--> 203\u001b[0m     \u001b[39mraise\u001b[39;00m \u001b[39mself\u001b[39m\u001b[39m.\u001b[39m_exception\u001b[39m.\u001b[39mwith_traceback(\u001b[39mself\u001b[39m\u001b[39m.\u001b[39m_exception_tb)\n\u001b[1;32m    204\u001b[0m \u001b[39mreturn\u001b[39;00m \u001b[39mself\u001b[39m\u001b[39m.\u001b[39m_result\n",
      "File \u001b[0;32m/opt/homebrew/Cellar/python@3.11/3.11.6/Frameworks/Python.framework/Versions/3.11/lib/python3.11/asyncio/tasks.py:277\u001b[0m, in \u001b[0;36mTask.__step\u001b[0;34m(***failed resolving arguments***)\u001b[0m\n\u001b[1;32m    273\u001b[0m \u001b[39mtry\u001b[39;00m:\n\u001b[1;32m    274\u001b[0m     \u001b[39mif\u001b[39;00m exc \u001b[39mis\u001b[39;00m \u001b[39mNone\u001b[39;00m:\n\u001b[1;32m    275\u001b[0m         \u001b[39m# We use the `send` method directly, because coroutines\u001b[39;00m\n\u001b[1;32m    276\u001b[0m         \u001b[39m# don't have `__iter__` and `__next__` methods.\u001b[39;00m\n\u001b[0;32m--> 277\u001b[0m         result \u001b[39m=\u001b[39m coro\u001b[39m.\u001b[39msend(\u001b[39mNone\u001b[39;00m)\n\u001b[1;32m    278\u001b[0m     \u001b[39melse\u001b[39;00m:\n\u001b[1;32m    279\u001b[0m         result \u001b[39m=\u001b[39m coro\u001b[39m.\u001b[39mthrow(exc)\n",
      "\u001b[1;32m/Users/supakornemchananon/workspace/Personal/dimsummaster/dev.ipynb Cell 5\u001b[0m line \u001b[0;36m2\n\u001b[1;32m      <a href='vscode-notebook-cell:/Users/supakornemchananon/workspace/Personal/dimsummaster/dev.ipynb#X15sZmlsZQ%3D%3D?line=0'>1</a>\u001b[0m \u001b[39masync\u001b[39;00m \u001b[39mdef\u001b[39;00m \u001b[39mget_drives\u001b[39m():\n\u001b[0;32m----> <a href='vscode-notebook-cell:/Users/supakornemchananon/workspace/Personal/dimsummaster/dev.ipynb#X15sZmlsZQ%3D%3D?line=1'>2</a>\u001b[0m     drives \u001b[39m=\u001b[39m \u001b[39mawait\u001b[39;00m graph_client\u001b[39m.\u001b[39mdrives\u001b[39m.\u001b[39mget()\n\u001b[1;32m      <a href='vscode-notebook-cell:/Users/supakornemchananon/workspace/Personal/dimsummaster/dev.ipynb#X15sZmlsZQ%3D%3D?line=2'>3</a>\u001b[0m     \u001b[39mif\u001b[39;00m drives \u001b[39mand\u001b[39;00m drives\u001b[39m.\u001b[39mvalue:\n\u001b[1;32m      <a href='vscode-notebook-cell:/Users/supakornemchananon/workspace/Personal/dimsummaster/dev.ipynb#X15sZmlsZQ%3D%3D?line=3'>4</a>\u001b[0m         \u001b[39mfor\u001b[39;00m drive \u001b[39min\u001b[39;00m drives\u001b[39m.\u001b[39mvalue:\n",
      "File \u001b[0;32m/opt/homebrew/lib/python3.11/site-packages/msgraph/generated/drives/drives_request_builder.py:64\u001b[0m, in \u001b[0;36mDrivesRequestBuilder.get\u001b[0;34m(self, request_configuration)\u001b[0m\n\u001b[1;32m     61\u001b[0m     \u001b[39mraise\u001b[39;00m \u001b[39mException\u001b[39;00m(\u001b[39m\"\u001b[39m\u001b[39mHttp core is null\u001b[39m\u001b[39m\"\u001b[39m) \n\u001b[1;32m     62\u001b[0m \u001b[39mfrom\u001b[39;00m \u001b[39m.\u001b[39;00m\u001b[39m.\u001b[39;00m\u001b[39mmodels\u001b[39;00m\u001b[39m.\u001b[39;00m\u001b[39mdrive_collection_response\u001b[39;00m \u001b[39mimport\u001b[39;00m DriveCollectionResponse\n\u001b[0;32m---> 64\u001b[0m \u001b[39mreturn\u001b[39;00m \u001b[39mawait\u001b[39;00m \u001b[39mself\u001b[39m\u001b[39m.\u001b[39mrequest_adapter\u001b[39m.\u001b[39msend_async(request_info, DriveCollectionResponse, error_mapping)\n",
      "File \u001b[0;32m/opt/homebrew/lib/python3.11/site-packages/kiota_http/httpx_request_adapter.py:185\u001b[0m, in \u001b[0;36mHttpxRequestAdapter.send_async\u001b[0;34m(self, request_info, parsable_factory, error_map)\u001b[0m\n\u001b[1;32m    182\u001b[0m     parent_span\u001b[39m.\u001b[39madd_event(RESPONSE_HANDLER_EVENT_INVOKED_KEY)\n\u001b[1;32m    183\u001b[0m     \u001b[39mreturn\u001b[39;00m \u001b[39mawait\u001b[39;00m response_handler\u001b[39m.\u001b[39mhandle_response_async(response, error_map)\n\u001b[0;32m--> 185\u001b[0m \u001b[39mawait\u001b[39;00m \u001b[39mself\u001b[39m\u001b[39m.\u001b[39mthrow_failed_responses(response, error_map, parent_span, parent_span)\n\u001b[1;32m    186\u001b[0m \u001b[39mif\u001b[39;00m \u001b[39mself\u001b[39m\u001b[39m.\u001b[39m_should_return_none(response):\n\u001b[1;32m    187\u001b[0m     \u001b[39mreturn\u001b[39;00m \u001b[39mNone\u001b[39;00m\n",
      "File \u001b[0;32m/opt/homebrew/lib/python3.11/site-packages/kiota_http/httpx_request_adapter.py:501\u001b[0m, in \u001b[0;36mHttpxRequestAdapter.throw_failed_responses\u001b[0;34m(self, response, error_map, parent_span, attribute_span)\u001b[0m\n\u001b[1;32m    492\u001b[0m         exc \u001b[39m=\u001b[39m APIError(\n\u001b[1;32m    493\u001b[0m             (\n\u001b[1;32m    494\u001b[0m                 \u001b[39m\"\u001b[39m\u001b[39mThe server returned an unexpected status code and the error registered\u001b[39m\u001b[39m\"\u001b[39m\n\u001b[0;32m   (...)\u001b[0m\n\u001b[1;32m    498\u001b[0m             response_headers,\n\u001b[1;32m    499\u001b[0m         )\n\u001b[1;32m    500\u001b[0m     _get_obj_span\u001b[39m.\u001b[39mend()\n\u001b[0;32m--> 501\u001b[0m     \u001b[39mraise\u001b[39;00m exc\n\u001b[1;32m    502\u001b[0m \u001b[39mfinally\u001b[39;00m:\n\u001b[1;32m    503\u001b[0m     _throw_failed_resp_span\u001b[39m.\u001b[39mend()\n",
      "\u001b[0;31mODataError\u001b[0m: \n        APIError\n        Code: 400\n        message: None\n        error: MainError(additional_data={}, code='BadRequest', details=None, inner_error=InnerError(additional_data={'date': DateTime(2023, 12, 17, 9, 58, 2, tzinfo=Timezone('UTC'))}, client_request_id='4e56b300-04c3-4030-bbf4-3b09e5c67395', date=None, odata_type=None, request_id='9f671f36-972e-4fbf-ab9e-a4ffc9fedfc0'), message='Tenant does not have a SPO license.', target=None)\n        "
     ]
    }
   ],
   "source": [
    "async def get_drives():\n",
    "    drives = await graph_client.drives.get()\n",
    "    if drives and drives.value:\n",
    "        for drive in drives.value:\n",
    "            print(drive.id, drive.drive_type, drive.name, drive.description, drive.web_url)\n",
    "\n",
    "\n",
    "asyncio.run(get_drives())"
   ]
  },
  {
   "cell_type": "code",
   "execution_count": null,
   "metadata": {},
   "outputs": [],
   "source": []
  }
 ],
 "metadata": {
  "kernelspec": {
   "display_name": "Python 3",
   "language": "python",
   "name": "python3"
  },
  "language_info": {
   "codemirror_mode": {
    "name": "ipython",
    "version": 3
   },
   "file_extension": ".py",
   "mimetype": "text/x-python",
   "name": "python",
   "nbconvert_exporter": "python",
   "pygments_lexer": "ipython3",
   "version": "3.11.6"
  },
  "orig_nbformat": 4
 },
 "nbformat": 4,
 "nbformat_minor": 2
}
